Workbook

Sheet List1
A1: jobname | B1: status | C1: startdate | D1: starttime | E1: spoolnumber | F1: done | G1: dbname | H1: elaubt
A2: ASCRIPT_RKWA_5K_DES_1 | B2: fertig | C2: 45909 | D2: 0.6274537 | E2: 9404639 | F2: X | G2: =_xlfn.REGEXREPLACE(REPLACE(A2,1,8,""),"_5K?_?D?E?S?.+","",,1) -> RKWA | H2: =VLOOKUP(G2,erlaubt!$A:$A,1,FALSE) -> #N/A | I2: =VLOOKUP(G2,ergebnis!E:E,1,FALSE) -> RKWA | J2: =VLOOKUP(List1!G2,Tabelle1!A:A,1,FALSE) -> #N/A
A3: ASCRIPT_RBKP_5K_DES_1 | B3: fertig | C3: 45909 | D3: 0.62686343 | E3: 9405044 | F3: X | G3: =_xlfn.REGEXREPLACE(REPLACE(A3,1,8,""),"_5K?_?D?E?S?.+","",,1) -> RBKP | H3: =VLOOKUP(G3,erlaubt!$A:$A,1,FALSE) -> #N/A | I3: =VLOOKUP(G3,ergebnis!E:E,1,FALSE) -> RBKP
A4: ASCRIPT_QBEW_5K_DES_1 | B4: fertig | C4: 45909 | D4: 0.61954861 | E4: 9404472 | F4: X | G4: =_xlfn.REGEXREPLACE(REPLACE(A4,1,8,""),"_5K?_?D?E?S?.+","",,1) -> QBEW | H4: =VLOOKUP(G4,erlaubt!$A:$A,1,FALSE) -> #N/A | I4: =VLOOKUP(G4,ergebnis!E:E,1,FALSE) -> QBEW
A5: ASCRIPT_MVER_5K_DES_1 | B5: fertig | C5: 45909 | D5: 0.6124537 | E5: 9405323 | F5: X | G5: =_xlfn.REGEXREPLACE(REPLACE(A5,1,8,""),"_5K?_?D?E?S?.+","",,1) -> MVER | H5: =VLOOKUP(G5,erlaubt!$A:$A,1,FALSE) -> #N/A | I5: =VLOOKUP(G5,ergebnis!E:E,1,FALSE) -> MVER
A6: ASCRIPT_MSPR_5K_DES_1 | B6: fertig | C6: 45909 | D6: 0.61174769 | E6: 9404292 | F6: X | G6: =_xlfn.REGEXREPLACE(REPLACE(A6,1,8,""),"_5K?_?D?E?S?.+","",,1) -> MSPR | H6: =VLOOKUP(G6,erlaubt!$A:$A,1,FALSE) -> #N/A | I6: =VLOOKUP(G6,ergebnis!E:E,1,FALSE) -> MSPR
A7: ASCRIPT_MSSL_5K_DES_1 | B7: fertig | C7: 45909 | D7: 0.61172454 | E7: 9405322 | F7: X | G7: =_xlfn.REGEXREPLACE(REPLACE(A7,1,8,""),"_5K?_?D?E?S?.+","",,1) -> MSSL | H7: =VLOOKUP(G7,erlaubt!$A:$A,1,FALSE) -> #N/A | I7: =VLOOKUP(G7,ergebnis!E:E,1,FALSE) -> MSSL
A8: ASCRIPT_MSLB_5K_DES_1 | B8: fertig | C8: 45909 | D8: 0.61106481 | E8: 9405220 | F8: X | G8: =_xlfn.REGEXREPLACE(REPLACE(A8,1,8,""),"_5K?_?D?E?S?.+","",,1) -> MSLB | H8: =VLOOKUP(G8,erlaubt!$A:$A,1,FALSE) -> #N/A | I8: =VLOOKUP(G8,ergebnis!E:E,1,FALSE) -> MSLB
A9: ASCRIPT_MSKU_5K_DES_1 | B9: fertig | C9: 45909 | D9: 0.61103009 | E9: 9404563 | F9: X | G9: =_xlfn.REGEXREPLACE(REPLACE(A9,1,8,""),"_5K?_?D?E?S?.+","",,1) -> MSKU | H9: =VLOOKUP(G9,erlaubt!$A:$A,1,FALSE) -> #N/A | I9: =VLOOKUP(G9,ergebnis!E:E,1,FALSE) -> MSKU
A10: ASCRIPT_MSKA_5K_DES_1 | B10: fertig | C10: 45909 | D10: 0.61019676 | E10: 9404637 | F10: X | G10: =_xlfn.REGEXREPLACE(REPLACE(A10,1,8,""),"_5K?_?D?E?S?.+","",,1) -> MSKA | H10: =VLOOKUP(G10,erlaubt!$A:$A,1,FALSE) -> #N/A | I10: =VLOOKUP(G10,ergebnis!E:E,1,FALSE) -> MSKA
A11: ASCRIPT_MSEG_5K_DES_1 | B11: fertig | C11: 45909 | D11: 0.61008102 | E11: 9404562 | F11: X | G11: =_xlfn.REGEXREPLACE(REPLACE(A11,1,8,""),"_5K?_?D?E?S?.+","",,1) -> MSEG | H11: =VLOOKUP(G11,erlaubt!$A:$A,1,FALSE) -> #N/A | I11: =VLOOKUP(G11,ergebnis!E:E,1,FALSE) -> MSEG
A12: ASCRIPT_MKPF_5K_DES_1 | B12: fertig | C12: 45909 | D12: 0.60841435 | E12: 9405041 | F12: X | G12: =_xlfn.REGEXREPLACE(REPLACE(A12,1,8,""),"_5K?_?D?E?S?.+","",,1) -> MKPF | H12: =VLOOKUP(G12,erlaubt!$A:$A,1,FALSE) -> #N/A | I12: =VLOOKUP(G12,ergebnis!E:E,1,FALSE) -> MKPF
A13: ASCRIPT_MKOL_5K_DES_1 | B13: fertig | C13: 45909 | D13: 0.60791667 | E13: 9404850 | F13: X | G13: =_xlfn.REGEXREPLACE(REPLACE(A13,1,8,""),"_5K?_?D?E?S?.+","",,1) -> MKOL | H13: =VLOOKUP(G13,erlaubt!$A:$A,1,FALSE) -> #N/A | I13: =VLOOKUP(G13,ergebnis!E:E,1,FALSE) -> MKOL
A14: ASCRIPT_MCHB_5K_DES_1 | B14: fertig | C14: 45909 | D14: 0.60511574 | E14: 9404561 | F14: X | G14: =_xlfn.REGEXREPLACE(REPLACE(A14,1,8,""),"_5K?_?D?E?S?.+","",,1) -> MCHB | H14: =VLOOKUP(G14,erlaubt!$A:$A,1,FALSE) -> #N/A | I14: =VLOOKUP(G14,ergebnis!E:E,1,FALSE) -> MCHB
... A57: ASCRIPT_/WRP/MPDEVSTSUM_5K_DES_ | B57: fertig | C57: 45909 | D57: 0.411875 | E57: 9404839 | F57: X | G57: =_xlfn.REGEXREPLACE(REPLACE(A57,1,8,""),"_5K?_?D?E?S?.+","",,1) -> /WRP/MPDEVSTSUM | H57: =VLOOKUP(G57,erlaubt!$A:$A,1,FALSE) -> #N/A | I57: =VLOOKUP(G57,ergebnis!E:E,1,FALSE) -> /WRP/MPDEVSTSUM

Sheet Tabelle1
A1: A016.xlsx
A2: A017.xlsx
A3: A018.xlsx
A4: A044.xlsx
A5: A619.xlsx
A6: A725.xlsx
A7: A915.xlsx
A8: A919.xlsx
A9: B025.xlsx
A10: B027.xlsx
A11: B048.xlsx
A12: B049.xlsx
... A54: _WUE_MP_ZSVW_ACC.xlsx

Sheet Tabelle2
A1: {=_xlfn.XLOOKUP(List1!#REF!,erlaubt!A:A,List1!A:G,"",0,1)} -> #REF!
A2: {=_xlfn.XLOOKUP(List1!#REF!,erlaubt!A:A,List1!A:G,"",0,1)} -> #REF!
A3: {=_xlfn.XLOOKUP(List1!#REF!,erlaubt!A:A,List1!A:G,"",0,1)} -> #REF!
A4: {=_xlfn.XLOOKUP(List1!#REF!,erlaubt!A:A,List1!A:G,"",0,1)} -> #REF!
A5: {=_xlfn.XLOOKUP(List1!#REF!,erlaubt!A:A,List1!A:G,"",0,1)} -> #REF!
A6: {=_xlfn.XLOOKUP(List1!#REF!,erlaubt!A:A,List1!A:G,"",0,1)} -> #REF!
A7: {=_xlfn.XLOOKUP(List1!#REF!,erlaubt!A:A,List1!A:G,"",0,1)} -> #REF!
A8: {=_xlfn.XLOOKUP(List1!#REF!,erlaubt!A:A,List1!A:G,"",0,1)} -> #REF!
A9: {=_xlfn.XLOOKUP(List1!#REF!,erlaubt!A:A,List1!A:G,"",0,1)} -> #REF!
A10: {=_xlfn.XLOOKUP(List1!#REF!,erlaubt!A:A,List1!A:G,"",0,1)} -> #REF!
A11: {=_xlfn.XLOOKUP(List1!#REF!,erlaubt!A:A,List1!A:G,"",0,1)} -> #REF!
A12: {=_xlfn.XLOOKUP(List1!#REF!,erlaubt!A:A,List1!A:G,"",0,1)} -> #REF!
... A37: {=_xlfn.XLOOKUP(List1!#REF!,erlaubt!A:A,List1!A:G,"",0,1)} -> #REF!
A38: {=_xlfn.XLOOKUP(List1!G2,erlaubt!A:A,List1!A:G,"",0,1)}
A39: {=_xlfn.XLOOKUP(List1!G3,erlaubt!A:A,List1!A:G,"",0,1)}
A40: {=_xlfn.XLOOKUP(List1!#REF!,erlaubt!A:A,List1!A:G,"",0,1)} -> #REF!
A41: {=_xlfn.XLOOKUP(List1!#REF!,erlaubt!A:A,List1!A:G,"",0,1)} -> #REF!
A42: {=_xlfn.XLOOKUP(List1!#REF!,erlaubt!A:A,List1!A:G,"",0,1)} -> #REF!
A43: {=_xlfn.XLOOKUP(List1!#REF!,erlaubt!A:A,List1!A:G,"",0,1)} -> #REF!
A44: {=_xlfn.XLOOKUP(List1!#REF!,erlaubt!A:A,List1!A:G,"",0,1)} -> #REF!
A45: {=_xlfn.XLOOKUP(List1!#REF!,erlaubt!A:A,List1!A:G,"",0,1)} -> #REF!
A46: {=_xlfn.XLOOKUP(List1!#REF!,erlaubt!A:A,List1!A:G,"",0,1)} -> #REF!
A47: {=_xlfn.XLOOKUP(List1!#REF!,erlaubt!A:A,List1!A:G,"",0,1)} -> #REF!
A48: {=_xlfn.XLOOKUP(List1!#REF!,erlaubt!A:A,List1!A:G,"",0,1)} -> #REF!
A49: {=_xlfn.XLOOKUP(List1!#REF!,erlaubt!A:A,List1!A:G,"",0,1)} -> #REF!
A50: {=_xlfn.XLOOKUP(List1!G4,erlaubt!A:A,List1!A:G,"",0,1)}
A51: {=_xlfn.XLOOKUP(List1!#REF!,erlaubt!A:A,List1!A:G,"",0,1)} -> #REF!
A52: {=_xlfn.XLOOKUP(List1!#REF!,erlaubt!A:A,List1!A:G,"",0,1)} -> #REF!
A53: {=_xlfn.XLOOKUP(List1!#REF!,erlaubt!A:A,List1!A:G,"",0,1)} -> #REF!
A54: {=_xlfn.XLOOKUP(List1!#REF!,erlaubt!A:A,List1!A:G,"",0,1)} -> #REF!
A55: {=_xlfn.XLOOKUP(List1!#REF!,erlaubt!A:A,List1!A:G,"",0,1)} -> #REF!
A56: {=_xlfn.XLOOKUP(List1!#REF!,erlaubt!A:A,List1!A:G,"",0,1)} -> #REF!
A57: {=_xlfn.XLOOKUP(List1!#REF!,erlaubt!A:A,List1!A:G,"",0,1)} -> #REF!
A58: {=_xlfn.XLOOKUP(List1!#REF!,erlaubt!A:A,List1!A:G,"",0,1)} -> #REF!
A59: {=_xlfn.XLOOKUP(List1!#REF!,erlaubt!A:A,List1!A:G,"",0,1)} -> #REF!
A60: {=_xlfn.XLOOKUP(List1!G5,erlaubt!A:A,List1!A:G,"",0,1)}
A61: {=_xlfn.XLOOKUP(List1!G6,erlaubt!A:A,List1!A:G,"",0,1)}
A62: {=_xlfn.XLOOKUP(List1!G7,erlaubt!A:A,List1!A:G,"",0,1)}
A63: {=_xlfn.XLOOKUP(List1!G8,erlaubt!A:A,List1!A:G,"",0,1)}
A64: {=_xlfn.XLOOKUP(List1!G9,erlaubt!A:A,List1!A:G,"",0,1)}
...

Sheet erlaubt
A1: EINE | F1: MCHA
A2: EKPO | F2: MCH1
A3: RSEG | F3: ZMB_NIWE_VERB
A4: S100 | F4: ZMB_NIWE_VERB_KM
A5: WYT1 | F5: ZMB_NIWE_VERB_KS
A6: S102 | F6: ZMB_NIWE_VERB_PM
A7: STAS | F7: ZMB_NIWE_VERB_KU
A8: STKO | F8: ZMB_NIWE_ROVB_KU
A9: STPO | F9: ZMB_NIWE_VERB_MJ
A10: STST | F10: RBKP
A11: STXH | F11: RSEG
A12: STZU | F12: MARD
... A34: ESDUS | F34: OBJK
F35: KONA
F36: S55/WUE/VDN_SETUP_C
F37: /WUE/MM_VDN
F38: /WUE/MMC_TAXES
F39: /WUE/MMC_TAX_REG
F40: /WUE/MMC_OTV_TAX
F41: /WUE/MM_PUR_SRV_LE
F42: ASMD
F43: TMP_SPEC
F44: ESSR
F45: ESLL
F46: /WUE/T_MM_PUR_TS
... F257: ZLO_VKNUM_LGORT

Sheet convertcsv
A1: Transaktion | B1: Prozesstyp | C1: Priorität | D1: Status | E1: Auftraggeber | F1: IRT-Status | G1: Geändert am | H1: ticketid | I1: ticketlink | J1: dbtab | K1: filename | L1: Spalte1 | M1: ticketuid | N1: erstellt? | O1: neu | P1: delete
A2: DEX-TM2-/SAPLOM/X__RELEV DEX<=>W4P diff#10967542 | B2: Störung | C2: 3: mittelEintrag erfolgreich validiert | D2: Neu | E2: Würth IT GmbH | G2: 9/11/2025 | H2: 10967542 | I2: https://fl.witglobal.net/#ServiceOrder-approve&/ticket/FAFFDFFC66021FD0A3DBFA25AC9A4D58 | J2: /SAPLOM/X__RELEV | K2: _SAPLOM_X__RELEV.htm | L2: =_xlfn.CONCAT("{ ",CHAR(34),"filename",CHAR(34),": ",CHAR(34),convertcsv[[#This Row],[neu]],CHAR(34),",",CHAR(34),"ticketuuid",CHAR(34),":"," ",CHAR(34),convertcsv[[#This Row],[ticketuid]],CHAR(34)," },") -> { "filename": "_SAPLOM_X__RELEV.xlsx","ticketuuid": "FAFFDFFC66021FD0A3DBFA25AC9A4D58" }, | M2: FAFFDFFC66021FD0A3DBFA25AC9A4D58 | N2: =VLOOKUP(convertcsv[[#This Row],[neu]],Tabelle1!$A$1:$A$55,1,FALSE) -> _SAPLOM_X__RELEV.xlsx | O2: =REPLACE(convertcsv[[#This Row],[filename]],FIND(".htm",convertcsv[[#This Row],[filename]]),4,".xlsx") -> _SAPLOM_X__RELEV.xlsx | P2: =convertcsv[[#This Row],[ticketuid]] & "," & convertcsv[[#This Row],[neu]] -> FAFFDFFC66021FD0A3DBFA25AC9A4D58,_SAPLOM_X__RELEV.xlsx
A3: DEX-TM2-/WRP/MPDEVSTSUM DEX<=>W4P diff#10967544 | B3: Störung | C3: 3: mittelEintrag erfolgreich validiert | D3: Neu | E3: Würth IT GmbH | G3: 9/11/2025 | H3: 10967544 | I3: https://fl.witglobal.net/#ServiceOrder-approve&/ticket/FAFFDFFC66021FD0A3DBFD707E128C55 | J3: /WRP/MPDEVSTSUM | K3: _WRP_MPDEVSTSUM.htm | L3: =_xlfn.CONCAT("{ ",CHAR(34),"filename",CHAR(34),": ",CHAR(34),convertcsv[[#This Row],[neu]],CHAR(34),",",CHAR(34),"ticketuuid",CHAR(34),":"," ",CHAR(34),convertcsv[[#This Row],[ticketuid]],CHAR(34)," },") -> { "filename": "_WRP_MPDEVSTSUM.xlsx","ticketuuid": "FAFFDFFC66021FD0A3DBFD707E128C55" }, | M3: FAFFDFFC66021FD0A3DBFD707E128C55 | N3: =VLOOKUP(convertcsv[[#This Row],[neu]],Tabelle1!$A$1:$A$55,1,FALSE) -> _WRP_MPDEVSTSUM.xlsx | O3: =REPLACE(convertcsv[[#This Row],[filename]],FIND(".htm",convertcsv[[#This Row],[filename]]),4,".xlsx") -> _WRP_MPDEVSTSUM.xlsx | P3: =convertcsv[[#This Row],[ticketuid]] & "," & convertcsv[[#This Row],[neu]] -> FAFFDFFC66021FD0A3DBFD707E128C55,_WRP_MPDEVSTSUM.xlsx
A4: DEX-TM2-/SAPLOM/X__BELEG DEX<=>W4P diff#10967543 | B4: Störung | C4: 3: mittelEintrag erfolgreich validiert | D4: Neu | E4: Würth IT GmbH | G4: 9/11/2025 | H4: 10967543 | I4: https://fl.witglobal.net/#ServiceOrder-approve&/ticket/FAFFDFFC66021FD0A3DBFBE22F9E1E63 | J4: /SAPLOM/X__BELEG | K4: _SAPLOM_X__BELEG.htm | L4: =_xlfn.CONCAT("{ ",CHAR(34),"filename",CHAR(34),": ",CHAR(34),convertcsv[[#This Row],[neu]],CHAR(34),",",CHAR(34),"ticketuuid",CHAR(34),":"," ",CHAR(34),convertcsv[[#This Row],[ticketuid]],CHAR(34)," },") -> { "filename": "_SAPLOM_X__BELEG.xlsx","ticketuuid": "FAFFDFFC66021FD0A3DBFBE22F9E1E63" }, | M4: FAFFDFFC66021FD0A3DBFBE22F9E1E63 | N4: =VLOOKUP(convertcsv[[#This Row],[neu]],Tabelle1!$A$1:$A$55,1,FALSE) -> _SAPLOM_X__BELEG.xlsx | O4: =REPLACE(convertcsv[[#This Row],[filename]],FIND(".htm",convertcsv[[#This Row],[filename]]),4,".xlsx") -> _SAPLOM_X__BELEG.xlsx | P4: =convertcsv[[#This Row],[ticketuid]] & "," & convertcsv[[#This Row],[neu]] -> FAFFDFFC66021FD0A3DBFBE22F9E1E63,_SAPLOM_X__BELEG.xlsx
A5: DEX-TM2-/WRP/MP_INBIDD DEX<=>W4P diff#10967541 | B5: Störung | C5: 3: mittelEintrag erfolgreich validiert | D5: Neu | E5: Würth IT GmbH | G5: 9/11/2025 | H5: 10967541 | I5: https://fl.witglobal.net/#ServiceOrder-approve&/ticket/FAFFDFFC66021FE0A3DBF87045F80247 | J5: /WRP/MP_INBIDD | K5: _WRP_MP_INBIDD.htm | L5: =_xlfn.CONCAT("{ ",CHAR(34),"filename",CHAR(34),": ",CHAR(34),convertcsv[[#This Row],[neu]],CHAR(34),",",CHAR(34),"ticketuuid",CHAR(34),":"," ",CHAR(34),convertcsv[[#This Row],[ticketuid]],CHAR(34)," },") -> { "filename": "_WRP_MP_INBIDD.xlsx","ticketuuid": "FAFFDFFC66021FE0A3DBF87045F80247" }, | M5: FAFFDFFC66021FE0A3DBF87045F80247 | N5: =VLOOKUP(convertcsv[[#This Row],[neu]],Tabelle1!$A$1:$A$55,1,FALSE) -> _WRP_MP_INBIDD.xlsx | O5: =REPLACE(convertcsv[[#This Row],[filename]],FIND(".htm",convertcsv[[#This Row],[filename]]),4,".xlsx") -> _WRP_MP_INBIDD.xlsx | P5: =convertcsv[[#This Row],[ticketuid]] & "," & convertcsv[[#This Row],[neu]] -> FAFFDFFC66021FE0A3DBF87045F80247,_WRP_MP_INBIDD.xlsx
A6: DEX-TM2-/WUE/BATNUM_IND DEX<=>W4P diff#10967539 | B6: Störung | C6: 3: mittelEintrag erfolgreich validiert | D6: Neu | E6: Würth IT GmbH | G6: 9/11/2025 | H6: 10967539 | I6: https://fl.witglobal.net/#ServiceOrder-approve&/ticket/FAFFDFFC66021FD0A3DBF6B925D612DF | J6: /WUE/BATNUM_IND | K6: _WUE_BATNUM_IND.htm | L6: =_xlfn.CONCAT("{ ",CHAR(34),"filename",CHAR(34),": ",CHAR(34),convertcsv[[#This Row],[neu]],CHAR(34),",",CHAR(34),"ticketuuid",CHAR(34),":"," ",CHAR(34),convertcsv[[#This Row],[ticketuid]],CHAR(34)," },") -> { "filename": "_WUE_BATNUM_IND.xlsx","ticketuuid": "FAFFDFFC66021FD0A3DBF6B925D612DF" }, | M6: FAFFDFFC66021FD0A3DBF6B925D612DF | N6: =VLOOKUP(convertcsv[[#This Row],[neu]],Tabelle1!$A$1:$A$55,1,FALSE) -> _WUE_BATNUM_IND.xlsx | O6: =REPLACE(convertcsv[[#This Row],[filename]],FIND(".htm",convertcsv[[#This Row],[filename]]),4,".xlsx") -> _WUE_BATNUM_IND.xlsx | P6: =convertcsv[[#This Row],[ticketuid]] & "," & convertcsv[[#This Row],[neu]] -> FAFFDFFC66021FD0A3DBF6B925D612DF,_WUE_BATNUM_IND.xlsx
A7: DEX-TM2-/WUE/MMC_PL_PO_P DEX<=>W4P diff#10967538 | B7: Störung | C7: 3: mittelEintrag erfolgreich validiert | D7: Neu | E7: Würth IT GmbH | G7: 9/11/2025 | H7: 10967538 | I7: https://fl.witglobal.net/#ServiceOrder-approve&/ticket/FAFFDFFC66021FD0A3DBF51AEA138EEB | J7: /WUE/MMC_PL_PO_P | K7: _WUE_MMC_PL_PO_P.htm | L7: =_xlfn.CONCAT("{ ",CHAR(34),"filename",CHAR(34),": ",CHAR(34),convertcsv[[#This Row],[neu]],CHAR(34),",",CHAR(34),"ticketuuid",CHAR(34),":"," ",CHAR(34),convertcsv[[#This Row],[ticketuid]],CHAR(34)," },") -> { "filename": "_WUE_MMC_PL_PO_P.xlsx","ticketuuid": "FAFFDFFC66021FD0A3DBF51AEA138EEB" }, | M7: FAFFDFFC66021FD0A3DBF51AEA138EEB | N7: =VLOOKUP(convertcsv[[#This Row],[neu]],Tabelle1!$A$1:$A$55,1,FALSE) -> _WUE_MMC_PL_PO_P.xlsx | O7: =REPLACE(convertcsv[[#This Row],[filename]],FIND(".htm",convertcsv[[#This Row],[filename]]),4,".xlsx") -> _WUE_MMC_PL_PO_P.xlsx | P7: =convertcsv[[#This Row],[ticketuid]] & "," & convertcsv[[#This Row],[neu]] -> FAFFDFFC66021FD0A3DBF51AEA138EEB,_WUE_MMC_PL_PO_P.xlsx
A8: DEX-TM2-/WUE/MMDIAB_PMAT DEX<=>W4P diff#10967534 | B8: Störung | C8: 3: mittelEintrag erfolgreich validiert | D8: Neu | E8: Würth IT GmbH | G8: 9/11/2025 | H8: 10967534 | I8: https://fl.witglobal.net/#ServiceOrder-approve&/ticket/FAFFDFFC66021FD0A3DBF36E5205D2DF | J8: /WUE/MMDIAB_PMAT | K8: _WUE_MMDIAB_PMAT.htm | L8: =_xlfn.CONCAT("{ ",CHAR(34),"filename",CHAR(34),": ",CHAR(34),convertcsv[[#This Row],[neu]],CHAR(34),",",CHAR(34),"ticketuuid",CHAR(34),":"," ",CHAR(34),convertcsv[[#This Row],[ticketuid]],CHAR(34)," },") -> { "filename": "_WUE_MMDIAB_PMAT.xlsx","ticketuuid": "FAFFDFFC66021FD0A3DBF36E5205D2DF" }, | M8: FAFFDFFC66021FD0A3DBF36E5205D2DF | N8: =VLOOKUP(convertcsv[[#This Row],[neu]],Tabelle1!$A$1:$A$55,1,FALSE) -> _WUE_MMDIAB_PMAT.xlsx | O8: =REPLACE(convertcsv[[#This Row],[filename]],FIND(".htm",convertcsv[[#This Row],[filename]]),4,".xlsx") -> _WUE_MMDIAB_PMAT.xlsx | P8: =convertcsv[[#This Row],[ticketuid]] & "," & convertcsv[[#This Row],[neu]] -> FAFFDFFC66021FD0A3DBF36E5205D2DF,_WUE_MMDIAB_PMAT.xlsx
A9: DEX-TM2-/WUE/MMV_NRVPROT DEX<=>W4P diff#10967533 | B9: Störung | C9: 3: mittelEintrag erfolgreich validiert | D9: Neu | E9: Würth IT GmbH | G9: 9/11/2025 | H9: 10967533 | I9: https://fl.witglobal.net/#ServiceOrder-approve&/ticket/FAFFDFFC66021FD0A3DBF1A08D38596A | J9: /WUE/MMV_NRVPROT | K9: _WUE_MMV_NRVPROT.htm | L9: =_xlfn.CONCAT("{ ",CHAR(34),"filename",CHAR(34),": ",CHAR(34),convertcsv[[#This Row],[neu]],CHAR(34),",",CHAR(34),"ticketuuid",CHAR(34),":"," ",CHAR(34),convertcsv[[#This Row],[ticketuid]],CHAR(34)," },") -> { "filename": "_WUE_MMV_NRVPROT.xlsx","ticketuuid": "FAFFDFFC66021FD0A3DBF1A08D38596A" }, | M9: FAFFDFFC66021FD0A3DBF1A08D38596A | N9: =VLOOKUP(convertcsv[[#This Row],[neu]],Tabelle1!$A$1:$A$55,1,FALSE) -> _WUE_MMV_NRVPROT.xlsx | O9: =REPLACE(convertcsv[[#This Row],[filename]],FIND(".htm",convertcsv[[#This Row],[filename]]),4,".xlsx") -> _WUE_MMV_NRVPROT.xlsx | P9: =convertcsv[[#This Row],[ticketuid]] & "," & convertcsv[[#This Row],[neu]] -> FAFFDFFC66021FD0A3DBF1A08D38596A,_WUE_MMV_NRVPROT.xlsx
A10: DEX-TM2-/WUE/MMV_TMSTAMP DEX<=>W4P diff#10967531 | B10: Störung | C10: 3: mittelEintrag erfolgreich validiert | D10: Neu | E10: Würth IT GmbH | G10: 9/11/2025 | H10: 10967531 | I10: https://fl.witglobal.net/#ServiceOrder-approve&/ticket/FAFFDFFC66021FD0A3DBEFD8D2B60E77 | J10: /WUE/MMV_TMSTAMP | K10: _WUE_MMV_TMSTAMP.htm | L10: =_xlfn.CONCAT("{ ",CHAR(34),"filename",CHAR(34),": ",CHAR(34),convertcsv[[#This Row],[neu]],CHAR(34),",",CHAR(34),"ticketuuid",CHAR(34),":"," ",CHAR(34),convertcsv[[#This Row],[ticketuid]],CHAR(34)," },") -> { "filename": "_WUE_MMV_TMSTAMP.xlsx","ticketuuid": "FAFFDFFC66021FD0A3DBEFD8D2B60E77" }, | M10: FAFFDFFC66021FD0A3DBEFD8D2B60E77 | N10: =VLOOKUP(convertcsv[[#This Row],[neu]],Tabelle1!$A$1:$A$55,1,FALSE) -> _WUE_MMV_TMSTAMP.xlsx | O10: =REPLACE(convertcsv[[#This Row],[filename]],FIND(".htm",convertcsv[[#This Row],[filename]]),4,".xlsx") -> _WUE_MMV_TMSTAMP.xlsx | P10: =convertcsv[[#This Row],[ticketuid]] & "," & convertcsv[[#This Row],[neu]] -> FAFFDFFC66021FD0A3DBEFD8D2B60E77,_WUE_MMV_TMSTAMP.xlsx
A11: DEX-TM2-/WUE/MMV_WKBASKE DEX<=>W4P diff#10967530 | B11: Störung | C11: 3: mittelEintrag erfolgreich validiert | D11: Neu | E11: Würth IT GmbH | G11: 9/11/2025 | H11: 10967530 | I11: https://fl.witglobal.net/#ServiceOrder-approve&/ticket/FAFFDFFC66021FD0A3DBEE21EC0DCFC3 | J11: /WUE/MMV_WKBASKE | K11: _WUE_MMV_WKBASKE.htm | L11: =_xlfn.CONCAT("{ ",CHAR(34),"filename",CHAR(34),": ",CHAR(34),convertcsv[[#This Row],[neu]],CHAR(34),",",CHAR(34),"ticketuuid",CHAR(34),":"," ",CHAR(34),convertcsv[[#This Row],[ticketuid]],CHAR(34)," },") -> { "filename": "_WUE_MMV_WKBASKE.xlsx","ticketuuid": "FAFFDFFC66021FD0A3DBEE21EC0DCFC3" }, | M11: FAFFDFFC66021FD0A3DBEE21EC0DCFC3 | N11: =VLOOKUP(convertcsv[[#This Row],[neu]],Tabelle1!$A$1:$A$55,1,FALSE) -> _WUE_MMV_WKBASKE.xlsx | O11: =REPLACE(convertcsv[[#This Row],[filename]],FIND(".htm",convertcsv[[#This Row],[filename]]),4,".xlsx") -> _WUE_MMV_WKBASKE.xlsx | P11: =convertcsv[[#This Row],[ticketuid]] & "," & convertcsv[[#This Row],[neu]] -> FAFFDFFC66021FD0A3DBEE21EC0DCFC3,_WUE_MMV_WKBASKE.xlsx
A12: DEX-TM2-/WUE/MP_ZSVW_ACC DEX<=>W4P diff#10967528 | B12: Störung | C12: 3: mittelEintrag erfolgreich validiert | D12: Neu | E12: Würth IT GmbH | G12: 9/11/2025 | H12: 10967528 | I12: https://fl.witglobal.net/#ServiceOrder-approve&/ticket/FAFFDFFC66021FD0A3DBEBCBE1A19F55 | J12: /WUE/MP_ZSVW_ACC | K12: _WUE_MP_ZSVW_ACC.htm | L12: =_xlfn.CONCAT("{ ",CHAR(34),"filename",CHAR(34),": ",CHAR(34),convertcsv[[#This Row],[neu]],CHAR(34),",",CHAR(34),"ticketuuid",CHAR(34),":"," ",CHAR(34),convertcsv[[#This Row],[ticketuid]],CHAR(34)," },") -> { "filename": "_WUE_MP_ZSVW_ACC.xlsx","ticketuuid": "FAFFDFFC66021FD0A3DBEBCBE1A19F55" }, | M12: FAFFDFFC66021FD0A3DBEBCBE1A19F55 | N12: =VLOOKUP(convertcsv[[#This Row],[neu]],Tabelle1!$A$1:$A$55,1,FALSE) -> _WUE_MP_ZSVW_ACC.xlsx | O12: =REPLACE(convertcsv[[#This Row],[filename]],FIND(".htm",convertcsv[[#This Row],[filename]]),4,".xlsx") -> _WUE_MP_ZSVW_ACC.xlsx | P12: =convertcsv[[#This Row],[ticketuid]] & "," & convertcsv[[#This Row],[neu]] -> FAFFDFFC66021FD0A3DBEBCBE1A19F55,_WUE_MP_ZSVW_ACC.xlsx
A13: DEX-TM2-A016 DEX<=>W4P diff#10967527 | B13: Störung | C13: 3: mittelEintrag erfolgreich validiert | D13: Neu | E13: Würth IT GmbH | G13: 9/11/2025 | H13: 10967527 | I13: https://fl.witglobal.net/#ServiceOrder-approve&/ticket/FAFFDFFC66021FD0A3DBEA06078E98A6 | J13: A016 | K13: A016.htm | L13: =_xlfn.CONCAT("{ ",CHAR(34),"filename",CHAR(34),": ",CHAR(34),convertcsv[[#This Row],[neu]],CHAR(34),",",CHAR(34),"ticketuuid",CHAR(34),":"," ",CHAR(34),convertcsv[[#This Row],[ticketuid]],CHAR(34)," },") -> { "filename": "A016.xlsx","ticketuuid": "FAFFDFFC66021FD0A3DBEA06078E98A6" }, | M13: FAFFDFFC66021FD0A3DBEA06078E98A6 | N13: =VLOOKUP(convertcsv[[#This Row],[neu]],Tabelle1!$A$1:$A$55,1,FALSE) -> A016.xlsx | O13: =REPLACE(convertcsv[[#This Row],[filename]],FIND(".htm",convertcsv[[#This Row],[filename]]),4,".xlsx") -> A016.xlsx | P13: =convertcsv[[#This Row],[ticketuid]] & "," & convertcsv[[#This Row],[neu]] -> FAFFDFFC66021FD0A3DBEA06078E98A6,A016.xlsx
... A57: DEX-TM2-RKWA DEX<=>W4P diff#10967458 | B57: Störung | C57: 3: mittelEintrag erfolgreich validiert | D57: Neu | E57: Würth IT GmbH | G57: 9/11/2025 | H57: 10967458 | I57: https://fl.witglobal.net/#ServiceOrder-approve&/ticket/FAFFDFFC66021FE0A3DB9C3D22EFC705 | J57: RKWA | K57: RKWA.htm | L57: =_xlfn.CONCAT("{ ",CHAR(34),"filename",CHAR(34),": ",CHAR(34),convertcsv[[#This Row],[neu]],CHAR(34),",",CHAR(34),"ticketuuid",CHAR(34),":"," ",CHAR(34),convertcsv[[#This Row],[ticketuid]],CHAR(34)," },") -> { "filename": "RKWA.xlsx","ticketuuid": "FAFFDFFC66021FE0A3DB9C3D22EFC705" }, | M57: FAFFDFFC66021FE0A3DB9C3D22EFC705 | N57: =VLOOKUP(convertcsv[[#This Row],[neu]],Tabelle1!$A$1:$A$55,1,FALSE) -> RKWA.xlsx | O57: =REPLACE(convertcsv[[#This Row],[filename]],FIND(".htm",convertcsv[[#This Row],[filename]]),4,".xlsx") -> RKWA.xlsx | P57: =convertcsv[[#This Row],[ticketuid]] & "," & convertcsv[[#This Row],[neu]] -> FAFFDFFC66021FE0A3DB9C3D22EFC705,RKWA.xlsx
A58: DEX-TM2-RSEG DEX<=>W4P diff#10966976 | B58: Störung | C58: 4: niedrig | D58: Neu | E58: Würth IT GmbH | G58: 9/10/2025 | H58: 10966976 | I58: https://fl.witglobal.net/#ServiceOrder-approve&/ticket/FAFFDFFC66021FE0A3CA094C8E2DDEC3 | J58: RSEG | K58: RSEG.htm | L58: =_xlfn.CONCAT("{ ",CHAR(34),"filename",CHAR(34),": ",CHAR(34),convertcsv[[#This Row],[neu]],CHAR(34),",",CHAR(34),"ticketuuid",CHAR(34),":"," ",CHAR(34),convertcsv[[#This Row],[ticketuid]],CHAR(34)," },") -> { "filename": "zu löschen","ticketuuid": "FAFFDFFC66021FE0A3CA094C8E2DDEC3" }, | M58: FAFFDFFC66021FE0A3CA094C8E2DDEC3 | N58: zu löschen | O58: zu löschen | P58: =convertcsv[[#This Row],[ticketuid]] & "," & convertcsv[[#This Row],[neu]] -> FAFFDFFC66021FE0A3CA094C8E2DDEC3,zu löschen
A59: DEX-TM2-S100 DEX<=>W4P diff#10966863 | B59: Störung | C59: 4: niedrig | D59: Neu | E59: Würth IT GmbH | G59: 9/10/2025 | H59: 10966863 | I59: https://fl.witglobal.net/#ServiceOrder-approve&/ticket/FAFFDFFC66021FD0A3C8BB18D4C759DC | J59: S100 | K59: S100.htm | L59: =_xlfn.CONCAT("{ ",CHAR(34),"filename",CHAR(34),": ",CHAR(34),convertcsv[[#This Row],[neu]],CHAR(34),",",CHAR(34),"ticketuuid",CHAR(34),":"," ",CHAR(34),convertcsv[[#This Row],[ticketuid]],CHAR(34)," },") -> { "filename": "zu löschen","ticketuuid": "FAFFDFFC66021FD0A3C8BB18D4C759DC" }, | M59: FAFFDFFC66021FD0A3C8BB18D4C759DC | N59: zu löschen | O59: zu löschen | P59: =convertcsv[[#This Row],[ticketuid]] & "," & convertcsv[[#This Row],[neu]] -> FAFFDFFC66021FD0A3C8BB18D4C759DC,zu löschen
A60: DEX-TM2-WYT1 DEX<=>W4P diff#10966611 | B60: Störung | C60: 4: niedrig | D60: Neu | E60: Würth IT GmbH | G60: 9/10/2025 | H60: 10966611 | I60: https://fl.witglobal.net/#ServiceOrder-approve&/ticket/FAFFDFFC66021FD0A3C46D0532D089FE | J60: WYT1 | K60: WYT1.htm | L60: =_xlfn.CONCAT("{ ",CHAR(34),"filename",CHAR(34),": ",CHAR(34),convertcsv[[#This Row],[neu]],CHAR(34),",",CHAR(34),"ticketuuid",CHAR(34),":"," ",CHAR(34),convertcsv[[#This Row],[ticketuid]],CHAR(34)," },") -> { "filename": "zu löschen","ticketuuid": "FAFFDFFC66021FD0A3C46D0532D089FE" }, | M60: FAFFDFFC66021FD0A3C46D0532D089FE | N60: zu löschen | O60: zu löschen | P60: =convertcsv[[#This Row],[ticketuid]] & "," & convertcsv[[#This Row],[neu]] -> FAFFDFFC66021FD0A3C46D0532D089FE,zu löschen
A61: DEX-TM2-S102 DEX<=>W4P diff#10966629 | B61: Störung | C61: 4: niedrig | D61: Neu | E61: Würth IT GmbH | G61: 9/10/2025 | H61: 10966629 | I61: https://fl.witglobal.net/#ServiceOrder-approve&/ticket/FAFFDFFC66021FD0A3C495BB27794DD8 | J61: S102 | K61: S102.htm | L61: =_xlfn.CONCAT("{ ",CHAR(34),"filename",CHAR(34),": ",CHAR(34),convertcsv[[#This Row],[neu]],CHAR(34),",",CHAR(34),"ticketuuid",CHAR(34),":"," ",CHAR(34),convertcsv[[#This Row],[ticketuid]],CHAR(34)," },") -> { "filename": "zu löschen","ticketuuid": "FAFFDFFC66021FD0A3C495BB27794DD8" }, | M61: FAFFDFFC66021FD0A3C495BB27794DD8 | N61: zu löschen | O61: zu löschen | P61: =convertcsv[[#This Row],[ticketuid]] & "," & convertcsv[[#This Row],[neu]] -> FAFFDFFC66021FD0A3C495BB27794DD8,zu löschen
A62: DEX-TM2-STAS DEX<=>W4P diff#10966623 | B62: Störung | C62: 4: niedrig | D62: Neu | E62: Würth IT GmbH | G62: 9/10/2025 | H62: 10966623 | I62: https://fl.witglobal.net/#ServiceOrder-approve&/ticket/FAFFDFFC66021FE0A3C487D73AD7C2D1 | J62: STAS | K62: STAS.htm | L62: =_xlfn.CONCAT("{ ",CHAR(34),"filename",CHAR(34),": ",CHAR(34),convertcsv[[#This Row],[neu]],CHAR(34),",",CHAR(34),"ticketuuid",CHAR(34),":"," ",CHAR(34),convertcsv[[#This Row],[ticketuid]],CHAR(34)," },") -> { "filename": "zu löschen","ticketuuid": "FAFFDFFC66021FE0A3C487D73AD7C2D1" }, | M62: FAFFDFFC66021FE0A3C487D73AD7C2D1 | N62: zu löschen | O62: zu löschen | P62: =convertcsv[[#This Row],[ticketuid]] & "," & convertcsv[[#This Row],[neu]] -> FAFFDFFC66021FE0A3C487D73AD7C2D1,zu löschen
A63: DEX-TM2-STKO DEX<=>W4P diff#10966620 | B63: Störung | C63: 4: niedrig | D63: Neu | E63: Würth IT GmbH | G63: 9/10/2025 | H63: 10966620 | I63: https://fl.witglobal.net/#ServiceOrder-approve&/ticket/FAFFDFFC66021FD0A3C480C8E6458787 | J63: STKO | K63: STKO.htm | L63: =_xlfn.CONCAT("{ ",CHAR(34),"filename",CHAR(34),": ",CHAR(34),convertcsv[[#This Row],[neu]],CHAR(34),",",CHAR(34),"ticketuuid",CHAR(34),":"," ",CHAR(34),convertcsv[[#This Row],[ticketuid]],CHAR(34)," },") -> { "filename": "zu löschen","ticketuuid": "FAFFDFFC66021FD0A3C480C8E6458787" }, | M63: FAFFDFFC66021FD0A3C480C8E6458787 | N63: zu löschen | O63: zu löschen | P63: =convertcsv[[#This Row],[ticketuid]] & "," & convertcsv[[#This Row],[neu]] -> FAFFDFFC66021FD0A3C480C8E6458787,zu löschen
A64: DEX-TM2-STPO DEX<=>W4P diff#10966617 | B64: Störung | C64: 4: niedrig | D64: Neu | E64: Würth IT GmbH | G64: 9/10/2025 | H64: 10966617 | I64: https://fl.witglobal.net/#ServiceOrder-approve&/ticket/FAFFDFFC66021FE0A3C47BDCA9FBD8AA | J64: STPO | K64: STPO.htm | L64: =_xlfn.CONCAT("{ ",CHAR(34),"filename",CHAR(34),": ",CHAR(34),convertcsv[[#This Row],[neu]],CHAR(34),",",CHAR(34),"ticketuuid",CHAR(34),":"," ",CHAR(34),convertcsv[[#This Row],[ticketuid]],CHAR(34)," },") -> { "filename": "zu löschen","ticketuuid": "FAFFDFFC66021FE0A3C47BDCA9FBD8AA" }, | M64: FAFFDFFC66021FE0A3C47BDCA9FBD8AA | N64: zu löschen | O64: zu löschen | P64: =convertcsv[[#This Row],[ticketuid]] & "," & convertcsv[[#This Row],[neu]] -> FAFFDFFC66021FE0A3C47BDCA9FBD8AA,zu löschen
A65: DEX-TM2-STST DEX<=>W4P diff#10966616 | B65: Störung | C65: 4: niedrig | D65: Neu | E65: Würth IT GmbH | G65: 9/10/2025 | H65: 10966616 | I65: https://fl.witglobal.net/#ServiceOrder-approve&/ticket/FAFFDFFC66021FD0A3C477FABD610692 | J65: STST | K65: STST.htm | L65: =_xlfn.CONCAT("{ ",CHAR(34),"filename",CHAR(34),": ",CHAR(34),convertcsv[[#This Row],[neu]],CHAR(34),",",CHAR(34),"ticketuuid",CHAR(34),":"," ",CHAR(34),convertcsv[[#This Row],[ticketuid]],CHAR(34)," },") -> { "filename": "zu löschen","ticketuuid": "FAFFDFFC66021FD0A3C477FABD610692" }, | M65: FAFFDFFC66021FD0A3C477FABD610692 | N65: zu löschen | O65: zu löschen | P65: =convertcsv[[#This Row],[ticketuid]] & "," & convertcsv[[#This Row],[neu]] -> FAFFDFFC66021FD0A3C477FABD610692,zu löschen
A66: DEX-TM2-STXH DEX<=>W4P diff#10966615 | B66: Störung | C66: 4: niedrig | D66: Neu | E66: Würth IT GmbH | G66: 9/10/2025 | H66: 10966615 | I66: https://fl.witglobal.net/#ServiceOrder-approve&/ticket/FAFFDFFC66021FE0A3C474C741655869 | J66: STXH | K66: STXH.htm | L66: =_xlfn.CONCAT("{ ",CHAR(34),"filename",CHAR(34),": ",CHAR(34),convertcsv[[#This Row],[neu]],CHAR(34),",",CHAR(34),"ticketuuid",CHAR(34),":"," ",CHAR(34),convertcsv[[#This Row],[ticketuid]],CHAR(34)," },") -> { "filename": "zu löschen","ticketuuid": "FAFFDFFC66021FE0A3C474C741655869" }, | M66: FAFFDFFC66021FE0A3C474C741655869 | N66: zu löschen | O66: zu löschen | P66: =convertcsv[[#This Row],[ticketuid]] & "," & convertcsv[[#This Row],[neu]] -> FAFFDFFC66021FE0A3C474C741655869,zu löschen
A67: DEX-TM2-STZU DEX<=>W4P diff#10966612 | B67: Störung | C67: 4: niedrig | D67: Neu | E67: Würth IT GmbH | G67: 9/10/2025 | H67: 10966612 | I67: https://fl.witglobal.net/#ServiceOrder-approve&/ticket/FAFFDFFC66021FD0A3C46F7C44A20792 | J67: STZU | K67: STZU.htm | L67: =_xlfn.CONCAT("{ ",CHAR(34),"filename",CHAR(34),": ",CHAR(34),convertcsv[[#This Row],[neu]],CHAR(34),",",CHAR(34),"ticketuuid",CHAR(34),":"," ",CHAR(34),convertcsv[[#This Row],[ticketuid]],CHAR(34)," },") -> { "filename": "zu löschen","ticketuuid": "FAFFDFFC66021FD0A3C46F7C44A20792" }, | M67: FAFFDFFC66021FD0A3C46F7C44A20792 | N67: zu löschen | O67: zu löschen | P67: =convertcsv[[#This Row],[ticketuid]] & "," & convertcsv[[#This Row],[neu]] -> FAFFDFFC66021FD0A3C46F7C44A20792,zu löschen
A68: DEX-TM2-T001W DEX<=>W4P diff#10966610 | B68: Störung | C68: 4: niedrig | D68: Neu | E68: Würth IT GmbH | G68: 9/10/2025 | H68: 10966610 | I68: https://fl.witglobal.net/#ServiceOrder-approve&/ticket/FAFFDFFC66021FD0A3C46BF690198E2B | J68: T001W | K68: T001W.htm | L68: =_xlfn.CONCAT("{ ",CHAR(34),"filename",CHAR(34),": ",CHAR(34),convertcsv[[#This Row],[neu]],CHAR(34),",",CHAR(34),"ticketuuid",CHAR(34),":"," ",CHAR(34),convertcsv[[#This Row],[ticketuid]],CHAR(34)," },") -> { "filename": "zu löschen","ticketuuid": "FAFFDFFC66021FD0A3C46BF690198E2B" }, | M68: FAFFDFFC66021FD0A3C46BF690198E2B | N68: zu löschen | O68: zu löschen | P68: =convertcsv[[#This Row],[ticketuid]] & "," & convertcsv[[#This Row],[neu]] -> FAFFDFFC66021FD0A3C46BF690198E2B,zu löschen
A69: DEX-TM2-VEPO DEX<=>W4P diff#10966608 | B69: Störung | C69: 4: niedrig | D69: Neu | E69: Würth IT GmbH | G69: 9/10/2025 | H69: 10966608 | I69: https://fl.witglobal.net/#ServiceOrder-approve&/ticket/FAFFDFFC66021FE0A3C469875B4B5F2B | J69: VEPO | K69: VEPO.htm | L69: =_xlfn.CONCAT("{ ",CHAR(34),"filename",CHAR(34),": ",CHAR(34),convertcsv[[#This Row],[neu]],CHAR(34),",",CHAR(34),"ticketuuid",CHAR(34),":"," ",CHAR(34),convertcsv[[#This Row],[ticketuid]],CHAR(34)," },") -> { "filename": "zu löschen","ticketuuid": "FAFFDFFC66021FE0A3C469875B4B5F2B" }, | M69: FAFFDFFC66021FE0A3C469875B4B5F2B | N69: zu löschen | O69: zu löschen | P69: =convertcsv[[#This Row],[ticketuid]] & "," & convertcsv[[#This Row],[neu]] -> FAFFDFFC66021FE0A3C469875B4B5F2B,zu löschen
... A89: DEX-TM2-ESDUS DEX<=>W4P diff#10966273 | B89: Störung | C89: 4: niedrig | D89: Neu | E89: Würth IT GmbH | G89: 9/9/2025 | H89: 10966273 | I89: https://fl.witglobal.net/#ServiceOrder-approve&/ticket/FAFFDFFC66021FE0A3B3D0B8D0F85C0C | J89: ESDUS | K89: ESDUS.htm | L89: =_xlfn.CONCAT("{ ",CHAR(34),"filename",CHAR(34),": ",CHAR(34),convertcsv[[#This Row],[neu]],CHAR(34),",",CHAR(34),"ticketuuid",CHAR(34),":"," ",CHAR(34),convertcsv[[#This Row],[ticketuid]],CHAR(34)," },") -> { "filename": "zu löschen","ticketuuid": "FAFFDFFC66021FE0A3B3D0B8D0F85C0C" }, | M89: FAFFDFFC66021FE0A3B3D0B8D0F85C0C | N89: zu löschen | O89: zu löschen | P89: =convertcsv[[#This Row],[ticketuid]] & "," & convertcsv[[#This Row],[neu]] -> FAFFDFFC66021FE0A3B3D0B8D0F85C0C,zu löschen

Sheet Tabelle3
A1: _WUE_MP_ZSVW_ACC__WUE_MMV_WKBASKE
A2: _WRP_MP_INBIDD__WRP_MMC_ADJINFR
A3: _WRP_MPDEVSTSUM__WRP_MMC_ADJINFR

Sheet Tabelle5
B1: https://fl.witglobal.net/#ServiceOrder-approve&amp;/ticket/FAFFDFFC66021FD0A3DDC584C7F21EA8
B2: https://fl.witglobal.net/#ServiceOrder-approve&amp;/ticket/FAFFDFFC66021FD0A3DBFA25AC9A4D58
B3: https://fl.witglobal.net/#ServiceOrder-approve&amp;/ticket/FAFFDFFC66021FD0A3DD0AF4052F457A
B4: https://fl.witglobal.net/#ServiceOrder-approve&amp;/ticket/FAFFDFFC66021FD0A3DBFD707E128C55
B5: https://fl.witglobal.net/#ServiceOrder-approve&amp;/ticket/FAFFDFFC66021FD0A3DBFBE22F9E1E63
B6: https://fl.witglobal.net/#ServiceOrder-approve&amp;/ticket/FAFFDFFC66021FE0A3DBF87045F80247
B7: https://fl.witglobal.net/#ServiceOrder-approve&amp;/ticket/FAFFDFFC66021FD0A3DBF6B925D612DF
B8: https://fl.witglobal.net/#ServiceOrder-approve&amp;/ticket/FAFFDFFC66021FD0A3DBF51AEA138EEB
B9: https://fl.witglobal.net/#ServiceOrder-approve&amp;/ticket/FAFFDFFC66021FD0A3DBF36E5205D2DF
B10: https://fl.witglobal.net/#ServiceOrder-approve&amp;/ticket/FAFFDFFC66021FD0A3DBF1A08D38596A
B11: https://fl.witglobal.net/#ServiceOrder-approve&amp;/ticket/FAFFDFFC66021FD0A3DBEFD8D2B60E77
B12: https://fl.witglobal.net/#ServiceOrder-approve&amp;/ticket/FAFFDFFC66021FD0A3DBEE21EC0DCFC3
... B98: https://fl.witglobal.net/#ServiceOrder-approve&amp;/ticket/D600A522E1021EEF8ED5325958D8112D

Sheet Tabelle4

Sheet ergebnis
A1: (index) | B1: Ticket ID | C1: Description | D1: Time
A2: 0 | B2: 10967458 | C2: DEX-TM2-RKWA DEX<=>W4P diff | D2: 2025-09-11T06:59:57.666Z | E2: =_xlfn.REGEXREPLACE(REPLACE(C2,1,8,"")," DEX.+","",,1) -> RKWA
A3: 1 | B3: 10967460 | C3: DEX-TM2-RBKP DEX<=>W4P diff | D3: 2025-09-11T07:00:21.607Z | E3: =_xlfn.REGEXREPLACE(REPLACE(C3,1,8,"")," DEX.+","",,1) -> RBKP
A4: 2 | B4: 10967463 | C4: DEX-TM2-QBEW DEX<=>W4P diff | D4: 2025-09-11T07:00:47.658Z | E4: =_xlfn.REGEXREPLACE(REPLACE(C4,1,8,"")," DEX.+","",,1) -> QBEW
A5: 3 | B5: 10967464 | C5: DEX-TM2-MVER DEX<=>W4P diff | D5: 2025-09-11T07:01:14.465Z | E5: =_xlfn.REGEXREPLACE(REPLACE(C5,1,8,"")," DEX.+","",,1) -> MVER
A6: 4 | B6: 10967467 | C6: DEX-TM2-MSPR DEX<=>W4P diff | D6: 2025-09-11T07:01:38.355Z | E6: =_xlfn.REGEXREPLACE(REPLACE(C6,1,8,"")," DEX.+","",,1) -> MSPR
A7: 5 | B7: 10967473 | C7: DEX-TM2-MSSL DEX<=>W4P diff | D7: 2025-09-11T07:02:03.071Z | E7: =_xlfn.REGEXREPLACE(REPLACE(C7,1,8,"")," DEX.+","",,1) -> MSSL
A8: 6 | B8: 10967474 | C8: DEX-TM2-MSLB DEX<=>W4P diff | D8: 2025-09-11T07:02:27.714Z | E8: =_xlfn.REGEXREPLACE(REPLACE(C8,1,8,"")," DEX.+","",,1) -> MSLB
A9: 7 | B9: 10967475 | C9: DEX-TM2-MSKU DEX<=>W4P diff | D9: 2025-09-11T07:02:51.102Z | E9: =_xlfn.REGEXREPLACE(REPLACE(C9,1,8,"")," DEX.+","",,1) -> MSKU
A10: 8 | B10: 10967476 | C10: DEX-TM2-MSKA DEX<=>W4P diff | D10: 2025-09-11T07:03:17.807Z | E10: =_xlfn.REGEXREPLACE(REPLACE(C10,1,8,"")," DEX.+","",,1) -> MSKA
A11: 9 | B11: 10967478 | C11: DEX-TM2-MSEG DEX<=>W4P diff | D11: 2025-09-11T07:03:40.990Z | E11: =_xlfn.REGEXREPLACE(REPLACE(C11,1,8,"")," DEX.+","",,1) -> MSEG
A12: 10 | B12: 10967479 | C12: DEX-TM2-MKPF DEX<=>W4P diff | D12: 2025-09-11T07:04:04.301Z | E12: =_xlfn.REGEXREPLACE(REPLACE(C12,1,8,"")," DEX.+","",,1) -> MKPF
A13: 11 | B13: 10967481 | C13: DEX-TM2-MKOL DEX<=>W4P diff | D13: 2025-09-11T07:04:27.568Z | E13: =_xlfn.REGEXREPLACE(REPLACE(C13,1,8,"")," DEX.+","",,1) -> MKOL
... A57: 55 | B57: 10967544 | C57: DEX-TM2-/WRP/MPDEVSTSUM DEX<=>W4P diff | D57: 2025-09-11T07:21:43.153Z | E57: =_xlfn.REGEXREPLACE(REPLACE(C57,1,8,"")," DEX.+","",,1) -> /WRP/MPDEVSTSUM
